(gprmax-env) C:\Users\TIH28\gprMax\batch_run\simulations_full_strategy_split\split_4\test>python collector.py
✅ Processing gpr_clay_r0_05_d0_2_a15 with 225 files
Traceback (most recent call last):
  File "<frozen runpy>", line 198, in _run_module_as_main
  File "<frozen runpy>", line 88, in _run_code
  File "C:\Users\TIH28\AppData\Roaming\Python\Python311\site-packages\tools\plot_Bscan.py", line 89, in <module>
    f = h5py.File(args.outputfile, 'r')
        ^^^^^^^^^^^^^^^^^^^^^^^^^^^^^^^
  File "C:\Users\TIH28\AppData\Roaming\Python\Python311\site-packages\h5py\_hl\files.py", line 564, in __init__
    fid = make_fid(name, mode, userblock_size, fapl, fcpl, swmr=swmr)
          ^^^^^^^^^^^^^^^^^^^^^^^^^^^^^^^^^^^^^^^^^^^^^^^^^^^^^^^^^^^
  File "C:\Users\TIH28\AppData\Roaming\Python\Python311\site-packages\h5py\_hl\files.py", line 238, in make_fid
    fid = h5f.open(name, flags, fapl=fapl)
          ^^^^^^^^^^^^^^^^^^^^^^^^^^^^^^^^
  File "h5py/_objects.pyx", line 56, in h5py._objects.with_phil.wrapper
  File "h5py/_objects.pyx", line 57, in h5py._objects.with_phil.wrapper
  File "h5py/h5f.pyx", line 102, in h5py.h5f.open
FileNotFoundError: [Errno 2] Unable to synchronously open file (unable to open file: name = 'gpr_clay_r0_05_d0_2_a15__merged.out', errno = 2, error message = 'No such file or directory', flags = 0, o_flags = 0)
❌ Error while processing gpr_clay_r0_05_d0_2_a15: Command '['python', '-m', 'tools.plot_Bscan', 'gpr_clay_r0_05_d0_2_a15__merged.out', 'Ez']' returned non-zero exit status 1.
⏩ Skipping gpr_clay_r0_05_d0_2_a90 — only 34 files found (needs 225)




gpr_clay_r0_05_d0_2_a15__merged.out
